Workbook
Name _Toc45260617: Таб.3.1_исходная!#REF!
Name _Toc45260617: Таб.3.1_полная!#REF!
Name Hchladice: #REF!
Name Hchladice: #REF!
Name Hchladice: #REF!
Name MaxVlhkost: #REF!
Name MaxVlhkost: #REF!
Name MaxVlhkost: #REF!
Name sub_1111: Таб.3.1_исходная!#REF!
Name sub_1111: Таб.3.1_полная!#REF!
Name sub_311: Таб.3.1_исходная!#REF!
Name sub_311: Таб.3.1_полная!#REF!
Name sub_312: Таб.3.1_исходная!#REF!
Name sub_312: Таб.3.1_полная!#REF!
Name sub_400: Таб.3.1_исходная!#REF!
Name sub_400: Таб.3.1_полная!#REF!
Name sub_41: Таб.3.1_исходная!#REF!
Name sub_41: Таб.3.1_полная!#REF!
Name sub_411: Таб.3.1_исходная!#REF!
Name sub_411: Таб.3.1_полная!#REF!
Name sub_412: Таб.3.1_исходная!#REF!
Name sub_412: Таб.3.1_полная!#REF!
Name sub_441: Таб.3.1_исходная!#REF!
Name sub_441: Таб.3.1_полная!#REF!
Name sub_4411: Таб.3.1_исходная!#REF!
Name sub_4411: Таб.3.1_полная!#REF!
Name Tchladice: #REF!
Name Tchladice: #REF!
Name Tchladice: #REF!
Name Tlak_vzduchu: #REF!
Name Tlak_vzduchu: #REF!
Name Tlak_vzduchu: #REF!
Name xchladice: #REF!
Name xchladice: #REF!
Name xchladice: #REF!
Name Аж: [1]МКД_ГВС_расчет!$C$22
Name Аж: [1]МКД_ГВС_расчет!$C$22
Name Аж: [2]МКД_ГВС_расчет!$C$22
Name Анж: [1]МКД_ГВС_расчет!$C$16
Name Анж: [1]МКД_ГВС_расчет!$C$16
Name Анж: [2]МКД_ГВС_расчет!$C$16
Name баланс: #REF!
Name баланс: #REF!
Name баланс: #REF!
Name площадьпола: #REF!
Name площадьпола: #REF!
Name площадьпола: #REF!
Name Теплоснабжение: [1]вспом_топливо!$A$2:$A$3
Name Теплоснабжение: [1]вспом_топливо!$A$2:$A$3
Name Теплоснабжение: [2]вспом_топливо!$A$2:$A$3
Name числолюдей: #REF!
Name числолюдей: #REF!
Name числолюдей: #REF!

Sheet Таб.3.1_полная
A1: Region | B1: City | C1: TWinterOut092 | D1: HeatingPeriodDuration | E1: HeatingPeriodAvgTemperature | F1: WinterRelativeHumidity | G1: WinterWindSpeed
A2: =Таб.3.1_исходная!A5 -> Республика Адыгея (Адыгея) | B2: =Таб.3.1_исходная!B5 -> Майкоп | C2: =Таб.3.1_исходная!F5 -> -16 | D2: =Таб.3.1_исходная!L5 -> 147 | E2: =Таб.3.1_исходная!M5 -> 2.5 | F2: =Таб.3.1_исходная!P5 -> 77 | G2: =Таб.3.1_исходная!T5 -> 3.6
A3: =Таб.3.1_исходная!A6 -> Республика Алтай | B3: =Таб.3.1_исходная!B6 -> Катанда | C3: =Таб.3.1_исходная!F6 -> -38 | D3: =Таб.3.1_исходная!L6 -> 233 | E3: =Таб.3.1_исходная!M6 -> -9 | F3: =Таб.3.1_исходная!P6 -> 80 | G3: =Таб.3.1_исходная!T6 -> 1.8
A4: =Таб.3.1_исходная!A7 -> Республика Алтай | B4: =Таб.3.1_исходная!B7 -> Кош-Агач | C4: =Таб.3.1_исходная!F7 -> -42 | D4: =Таб.3.1_исходная!L7 -> 256 | E4: =Таб.3.1_исходная!M7 -> -12 | F4: =Таб.3.1_исходная!P7 -> 81 | G4: =Таб.3.1_исходная!T7 -> 3.3
A5: =Таб.3.1_исходная!A8 -> Республика Алтай | B5: =Таб.3.1_исходная!B8 -> Онгудай | C5: =Таб.3.1_исходная!F8 -> -36 | D5: =Таб.3.1_исходная!L8 -> 228 | E5: =Таб.3.1_исходная!M8 -> -8 | F5: =Таб.3.1_исходная!P8 -> 78 | G5: =Таб.3.1_исходная!T8 -> 2.1
A6: =Таб.3.1_исходная!A9 -> Республика Алтай | B6: =Таб.3.1_исходная!B9 -> Яйлю | C6: =Таб.3.1_исходная!F9 -> -24 | D6: =Таб.3.1_исходная!L9 -> 224 | E6: =Таб.3.1_исходная!M9 -> -2.4 | F6: =Таб.3.1_исходная!P9 -> 66 | G6: =Таб.3.1_исходная!T9 -> 3.7
A7: =Таб.3.1_исходная!A10 -> Алтайский край | B7: =Таб.3.1_исходная!B10 -> Алейск | C7: =Таб.3.1_исходная!F10 -> -35 | D7: =Таб.3.1_исходная!L10 -> 209 | E7: =Таб.3.1_исходная!M10 -> -7.4 | F7: =Таб.3.1_исходная!P10 -> 77 | G7: =Таб.3.1_исходная!T10 -> 5.9
A8: =Таб.3.1_исходная!A11 -> Алтайский край | B8: =Таб.3.1_исходная!B11 -> Барнаул | C8: =Таб.3.1_исходная!F11 -> -36 | D8: =Таб.3.1_исходная!L11 -> 214 | E8: =Таб.3.1_исходная!M11 -> -7.5 | F8: =Таб.3.1_исходная!P11 -> 77 | G8: =Таб.3.1_исходная!T11 -> 3.9
A9: =Таб.3.1_исходная!A12 -> Алтайский край | B9: =Таб.3.1_исходная!B12 -> Бийск | C9: =Таб.3.1_исходная!F12 -> -37 | D9: =Таб.3.1_исходная!L12 -> 213 | E9: =Таб.3.1_исходная!M12 -> -7.6 | F9: =Таб.3.1_исходная!P12 -> 78 | G9: =Таб.3.1_исходная!T12 -> 4.9
A10: =Таб.3.1_исходная!A13 -> Алтайский край | B10: =Таб.3.1_исходная!B13 -> Змеиногорск | C10: =Таб.3.1_исходная!F13 -> -37 | D10: =Таб.3.1_исходная!L13 -> 211 | E10: =Таб.3.1_исходная!M13 -> -6.7 | F10: =Таб.3.1_исходная!P13 -> 74 | G10: =Таб.3.1_исходная!T13 -> 5.2
A11: =Таб.3.1_исходная!A14 -> Алтайский край | B11: =Таб.3.1_исходная!B14 -> Родино | C11: =Таб.3.1_исходная!F14 -> -37 | D11: =Таб.3.1_исходная!L14 -> 207 | E11: =Таб.3.1_исходная!M14 -> -8 | F11: =Таб.3.1_исходная!P14 -> 78 | G11: =Таб.3.1_исходная!T14 -> 5.9
A12: =Таб.3.1_исходная!A15 -> Алтайский край | B12: =Таб.3.1_исходная!B15 -> Рубцовск | C12: =Таб.3.1_исходная!F15 -> -37 | D12: =Таб.3.1_исходная!L15 -> 207 | E12: =Таб.3.1_исходная!M15 -> -7.8 | F12: =Таб.3.1_исходная!P15 -> 76 | G12: =Таб.3.1_исходная!T15 -> 7.1
A13: =Таб.3.1_исходная!A16 -> Алтайский край | B13: =Таб.3.1_исходная!B16 -> Славгород | C13: =Таб.3.1_исходная!F16 -> -37 | D13: =Таб.3.1_исходная!L16 -> 206 | E13: =Таб.3.1_исходная!M16 -> -8.8 | F13: =Таб.3.1_исходная!P16 -> 80 | G13: =Таб.3.1_исходная!T16 -> 4.9
... A525: =Таб.3.1_исходная!A528 -> 0 | B525: =Таб.3.1_исходная!B528 -> 0 | C525: =Таб.3.1_исходная!F528 -> 0 | D525: =Таб.3.1_исходная!L528 -> 0 | E525: =Таб.3.1_исходная!M528 -> 0 | F525: =Таб.3.1_исходная!P528 -> 0 | G525: =Таб.3.1_исходная!T528 -> 0

Sheet Таб.3.1_исходная
A1: Республика, край, автономный округ, область | B1: Населенный пункт | C1: Температура воздуха наиболее холодных суток, °С, обеспеченностью | E1: Температура воздуха наиболее холодной пятидневки, °С, обеспеченностью | G1: Температура воздуха, °С, обеспеченностью 0,94 | H1: Абсолютная минимальная температура воздуха, °С | I1: Средняя суточная амплитуда температуры воздуха наиболее холодного месяца, °С | J1: Продолжительность, сут, и средняя температура воздуха, °С, периода со средней суточной температурой воздуха | P1: Средняя месячная относительная влажность воздуха наиболее холодного месяца, % | Q1: Средняя месячная относительная влажность воздуха в 15 ч наиболее холодного месяца, % | R1: Количество осадков за ноябрь - март, мм | S1: Преобладающее направление ветра за декабрь - февраль | T1: Максимальная из средних скоростей ветра по румбам за январь, м/с | U1: Средняя скорость ветра, м/с, за период со сред ней суточной температурой воздуха 8°С | V1: https://lsk-lskos.ru/sk
J2: ≤0°С | L2: ≤8°С | N2: ≤10°С
C3: 0.98 | D3: 0.92 | E3: 0.98 | F3: 0.92 | J3: продолжительность, сут. | K3: средняя температура, °С | L3: продолжительность, сут. | M3: средняя температура, °С | N3: продолжительность, сут. | O3: средняя температура, °С
A4: 1 | B4: 1 | C4: 2 | D4: 3 | E4: 4 | F4: 5 | G4: 6 | H4: 7 | I4: 8 | J4: 9 | K4: 10 | L4: 11 | M4: 12 | N4: 13 | O4: 14 | P4: 15 | Q4: 16 | R4: 17 | S4: 18 | T4: 19 | U4: 20
A5: Республика Адыгея (Адыгея) | B5: Майкоп | C5: -22 | D5: -19 | E5: -18 | F5: -16 | G5: -6 | H5: -34 | I5: 8.4 | J5: 34 | K5: -0.2 | L5: 147 | M5: 2.5 | N5: 167 | O5: 3.2 | P5: 77 | Q5: 68 | R5: 293 | S5: Ю | T5: 3.6 | U5: 3.3
A6: Республика Алтай | B6: Катанда | C6: -43 | D6: -40 | E6: -42 | F6: -38 | G6: -27 | H6: -48 | I6: 12.1 | J6: 171 | K6: -13.9 | L6: 233 | M6: -9 | N6: 255 | O6: -7.5 | P6: 80 | Q6: 76 | R6: 67 | S6: С | T6: 1.8 | U6: 0.7
A7: Республика Алтай | B7: Кош-Агач | C7: -47 | D7: -44 | E7: -45 | F7: -42 | G7: -32 | H7: -55 | I7: 11.5 | J7: 190 | K7: -17.6 | L7: 256 | M7: -12 | N7: 273 | O7: -10.7 | P7: 81 | Q7: 76 | R7: 15 | S7: В | T7: 3.3 | U7: 1.5
A8: Республика Алтай | B8: Онгудай | C8: -41 | D8: -38 | E8: -39 | F8: -36 | G8: -26 | H8: -46 | I8: 10.5 | J8: 164 | K8: -12.8 | L8: 228 | M8: -8 | N8: 247 | O8: -6.7 | P8: 78 | Q8: 72 | R8: 42 | S8: СЗ | T8: 2.1 | U8: 0.5
A9: Республика Алтай | B9: Яйлю | C9: -31 | D9: -28 | E9: -26 | F9: -24 | G9: -13 | H9: -39 | I9: 9 | J9: 148 | K9: -5.8 | L9: 224 | M9: -2.4 | N9: 246 | O9: -1.4 | P9: 66 | Q9: 62 | R9: 132 | S9: В | T9: 3.7 | U9: 2.1
A10: Алтайский край | B10: Алейск | C10: -41 | D10: -38 | E10: -38 | F10: -35 | G10: -24 | H10: -47 | I10: 9.4 | J10: 160 | K10: -11 | L10: 209 | M10: -7.4 | N10: 225 | O10: -6.3 | P10: 77 | Q10: 74 | R10: 131 | S10: ЮЗ | T10: 5.9 | U10: 3.4
A11: Алтайский край | B11: Барнаул | C11: -41 | D11: -40 | E11: -39 | F11: -36 | G11: -23 | H11: -52 | I11: 10 | J11: 163 | K11: -11.1 | L11: 214 | M11: -7.5 | N11: 231 | O11: -6.2 | P11: 77 | Q11: 71 | R11: 125 | S11: ЮЗ | T11: 3.9 | U11: 3.4
A12: Алтайский край | B12: Бийск | C12: -44 | D12: -42 | E12: -41 | F12: -37 | G12: -23 | H12: -51 | I12: 12 | J12: 163 | K12: -11.3 | L12: 213 | M12: -7.6 | N12: 230 | O12: -6.4 | P12: 78 | Q12: 72 | R12: 186 | S12: ЮЗ | T12: 4.9 | U12: 2.3
A13: Алтайский край | B13: Змеиногорск | C13: -44 | D13: -41 | E13: -42 | F13: -37 | G13: -23 | H13: -49 | I13: 12.2 | J13: 159 | K13: -10.2 | L13: 211 | M13: -6.7 | N13: 229 | O13: -5.4 | P13: 74 | Q13: 66 | R13: 263 | S13: Ю | T13: 5.2 | U13: 3.2
A14: Алтайский край | B14: Родино | C14: -44 | D14: -41 | E14: -40 | F14: -37 | G14: -23 | H14: -49 | I14: 9.8 | J14: 162 | K14: -11.4 | L14: 207 | M14: -8 | N14: 223 | O14: -6.7 | P14: 78 | Q14: 75 | R14: 98 | S14: Ю | T14: 5.9 | U14: 4.5
A15: Алтайский край | B15: Рубцовск | C15: -43 | D15: -41 | E15: -40 | F15: -37 | G15: -22 | H15: -49 | I15: 10.2 | J15: 160 | K15: -11.4 | L15: 207 | M15: -7.8 | N15: 222 | O15: -6.6 | P15: 76 | Q15: 74 | R15: 96 | S15: Ю | T15: 7.1 | U15: 5.3
A16: Алтайский край | B16: Славгород | C16: -44 | D16: -41 | E16: -40 | F16: -37 | G16: -24 | H16: -48 | I16: 9.5 | J16: 162 | K16: -12.3 | L16: 206 | M16: -8.8 | N16: 222 | O16: -7.5 | P16: 80 | Q16: 76 | R16: 93 | S16: Ю | T16: 4.9 | U16: 4.1
... A25: Амурская область | B25: Завитинск | C25: -38 | D25: -36 | E25: -35 | F25: -34 | G25: -30 | H25: -46 | I25: 10.1 | J25: 178 | K25: -17.4 | L25: 225 | M25: -12.9 | N25: 241 | O25: -11.4 | P25: 76 | Q25: 70 | R25: 57 | S25: СЗ | T25: 2.1 | U25: 1.9
A26: Амурская область | B26: Зея | C26: -46 | D26: -44 | E26: -43 | F26: -42 | G26: -35 | H26: -52 | I26: 14.7 | J26: 190 | K26: -19.5 | L26: 239 | M26: -14.6 | N26: 255 | O26: -13.1 | P26: 69 | Q26: 63 | R26: 35 | S26: С | T26: 3.5 | U26: -
A27: Амурская область | B27: Норск | C27: -45 | D27: -43 | E27: -44 | F27: -41 | G27: -35 | H27: -55 | I27: 13.9 | J27: 179 | K27: -19.5 | L27: 227 | M27: -14.5 | N27: 243 | O27: -13 | P27: 72 | Q27: 67 | R27: 51 | S27: СВ | T27: 2.1 | U27: 1
A28: Амурская область | B28: Поярково | C28: -40 | D28: -38 | E28: -37 | F28: -35 | G28: -30 | H28: -46 | I28: 11.8 | J28: 167 | K28: -16.4 | L28: 212 | M28: -12 | N28: 227 | O28: -10.6 | P28: 75 | Q28: 70 | R28: 49 | S28: З | T28: 2.5 | U28: 2
A29: Амурская область | B29: Свободный | C29: -42 | D29: -40 | E29: -39 | F29: -37 | G29: -30 | H29: -50 | I29: 11.7 | J29: 176 | K29: -17.1 | L29: 222 | M29: -12.6 | N29: 237 | O29: -11.3 | P29: 70 | Q29: 63 | R29: 50 | S29: З, СЗ | T29: 2.9 | U29: 2.6
A30: Амурская область | B30: Сковородино | C30: -44 | D30: -42 | E30: -42 | F30: -39 | G30: -34 | H30: -52 | I30: 14.5 | J30: 193 | K30: -18.6 | L30: 244 | M30: -13.8 | N30: 260 | O30: -12.4 | P30: 73 | Q30: 65 | R30: 32 | S30: СВ | T30: 2.3 | U30: 2.2
A31: Амурская область | B31: Тында | C31: -45 | D31: -43 | E31: -42 | F31: -40 | G31: -33 | H31: -51 | I31: 10.4 | J31: 199 | K31: -19.1 | L31: 250 | M31: -14.4 | N31: 265 | O31: -13.1 | P31: 74 | Q31: 70 | R31: 52 | S31: З | T31: 3 | U31: 2
A32: Амурская область | B32: Усть-Нюкжа | C32: -47 | D32: -45 | E32: -44 | F32: -43 | G32: -35 | H32: -51 | I32: 7.8 | J32: 200 | K32: -19.9 | L32: 252 | M32: -15 | N32: 266 | O32: -13.7 | P32: 77 | Q32: 74 | R32: 35 | S32: С | T32: 1.8 | U32: 0.6
A33: Амурская область | B33: Черняево | C33: -45 | D33: -43 | E33: -42 | F33: -40 | G33: -34 | H33: -51 | I33: 13.5 | J33: 180 | K33: -17.7 | L33: 229 | M33: -13 | N33: 244 | O33: -11.7 | P33: 72 | Q33: 64 | R33: 32 | S33: З | T33: 3.7 | U33: 1.9
A34: Амурская область | B34: Шимановск | C34: -41 | D34: -40 | E34: -39 | F34: -37 | G34: -30 | H34: -49 | I34: 12.9 | J34: 179 | K34: -17 | L34: 228 | M34: -12.4 | N34: 243 | O34: -11.1 | P34: 72 | Q34: 65 | R34: 42 | S34: СЗ | T34: 3.1 | U34: 2.1
A35: Амурская область | B35: Экимчан | C35: -45 | D35: -44 | E35: -43 | F35: -42 | G35: -35 | H35: -53 | I35: 10.7 | J35: 195 | K35: -19.4 | L35: 247 | M35: -14.4 | N35: 263 | O35: -13 | P35: 74 | Q35: 67 | R35: 67 | S35: В | T35: 1.6 | U35: 1.3
A36: Архангельская область | B36: Архангельск | C36: -40 | D36: -38 | E36: -37 | F36: -34 | G36: -20 | H36: -45 | I36: 8.3 | J36: 175 | K36: -8.1 | L36: 248 | M36: -4.5 | N36: 270 | O36: -3.4 | P36: 85 | Q36: 84 | R36: 188 | S36: ЮВ | T36: 3.6 | U36: 3.1
A37: Архангельская область | B37: Емецк | C37: -38 | D37: -36 | E37: -35 | F37: -32 | G37: -20 | H37: -48 | I37: 6.9 | J37: 175 | K37: -8.5 | L37: 244 | M37: -4.9 | N37: 265 | O37: -3.8 | P37: 84 | Q37: 84 | R37: 159 | S37: Ю | T37: 4.8 | U37: 3.7
A38: Архангельская область | B38: Каргополь | C38: -37 | D38: -34 | E38: -32 | F38: -29 | G38: -18 | H38: -44 | I38: 8.3 | J38: 167 | K38: -7.7 | L38: 235 | M38: -4.3 | N38: 255 | O38: -3.2 | P38: 86 | Q38: 85 | R38: 205 | S38: Ю | T38: 3.6 | U38: 3
... A75: Воронежская область | B75: Воронеж | C75: -30 | D75: -28 | E75: -26 | F75: -24 | G75: -12 | H75: -37 | I75: 6.6 | J75: 130 | K75: -5.3 | L75: 190 | M75: -2.4 | N75: 205 | O75: -1.5 | P75: 83 | Q75: 78 | R75: 206 | S75: З | T75: 4 | U75: 3.2
A76: Республика Дагестан | B76: Дербент | C76: -13 | D76: -11 | E76: -9 | F76: -7 | G76: 0 | H76: -19 | I76: 5 | J76: 0 | K76: - | L76: 136 | M76: 4 | N76: 158 | O76: 4.7 | P76: 83 | Q76: 80 | R76: 184 | S76: СЗ | T76: 3.2 | U76: 2.1
A77: Республика Дагестан | B77: Махачкала | C77: -20 | D77: -17 | E77: -15 | F77: -13 | G77: -2 | H77: -27 | I77: 5.9 | J77: 0 | K77: - | L77: 145 | M77: 2.8 | N77: 165 | O77: 3.6 | P77: 83 | Q77: 79 | R77: 151 | S77: СЗ, З | T77: 5.2 | U77: 3.9
A78: Республика Дагестан | B78: Терекли-Мектеб | C78: -24 | D78: -22 | E78: -20 | F78: -17 | G78: -5 | H78: -35 | I78: 6.5 | J78: 69 | K78: -1.4 | L78: 155 | M78: 1.4 | N78: 172 | O78: 2.2 | P78: 88 | Q78: 81 | R78: 109 | S78: В | T78: 3.7 | U78: 2.8
A79: Еврейская автономная область | B79: Биробиджан | C79: -34 | D79: -33 | E79: -32 | F79: -31 | G79: -26 | H79: -43 | I79: 15.3 | J79: 161 | K79: -14.5 | L79: 210 | M79: -10.1 | N79: 225 | O79: -8.9 | P79: 75 | Q79: 67 | R79: 81 | S79: З | T79: 2.6 | U79: 1.6
A80: Еврейская автономная область | B80: Екатерино-Никольское | C80: -33 | D80: -31 | E80: -30 | F80: -29 | G80: -22 | H80: -40 | I80: 10.2 | J80: 159 | K80: -13.1 | L80: 205 | M80: -9.2 | N80: 220 | O80: -8 | P80: 70 | Q80: 60 | R80: 53 | S80: СЗ | T80: 4.5 | U80: 2.2
A81: Еврейская автономная область | B81: Облучье | C81: -40 | D81: -39 | E81: -37 | F81: -36 | G81: -29 | H81: -46 | I81: 13.1 | J81: 173 | K81: -16.7 | L81: 221 | M81: -12.1 | N81: 237 | O81: -10.7 | P81: 73 | Q81: 67 | R81: 82 | S81: С | T81: 1.9 | U81: 1.5
A82: Забайкальский край | B82: Агинское | C82: -40 | D82: -37 | E82: -36 | F82: -34 | G82: -27 | H82: -48 | I82: 14 | J82: 181 | K82: -14.9 | L82: 237 | M82: -10.4 | N82: 251 | O82: -9.3 | P82: 72 | Q82: 65 | R82: 21 | S82: З | T82: 3.7 | U82: 2.9
A83: Забайкальский край | B83: Акша | C83: -38 | D83: -36 | E83: -35 | F83: -34 | G83: -27 | H83: -50 | I83: 14.8 | J83: 179 | K83: -14.4 | L83: 235 | M83: -9.9 | N83: 251 | O83: -8.7 | P83: 75 | Q83: 68 | R83: 16 | S83: Ю | T83: 4.5 | U83: 2.5
A84: Забайкальский край | B84: Александровский Завод | C84: -40 | D84: -39 | E84: -39 | F84: -37 | G84: -30 | H84: -48 | I84: 14.9 | J84: 190 | K84: -17.1 | L84: 247 | M84: -12.2 | N84: 264 | O84: -10.8 | P84: 77 | Q84: 70 | R84: 25 | S84: Ю | T84: 2.4 | U84: 2.1
...
